Workbook

Sheet Läs mig
A1: Övningsbanken – CAP Online
A2: Alla övningar som finns i appen i dag (2026-10-26). Fyll på med dina egna övningar och tagga dem, så kan vi planera pass och läsa in listan i appen igen.
A4: Övningar i banken | B4: =COUNTA('Övningar'!$B$3:$B$500)
A5: – varav med film | B5: =COUNTIF('Övningar'!$N$3:$N$500,"Ja")
A6: – varav utan film (att filma) | B6: =COUNTIF('Övningar'!$N$3:$N$500,"Nej")
A7: Filmer | B7: =COUNTA('Filmer'!$A$2:$A$80)
A8: Kunskapstexter | B8: =COUNTA('Kunskap'!$A$2:$A$200)
A10: Så här fyller du i
A11: Fliken Övningar | B11: En rad per övning. Raderna som redan finns kommer från appen. Lägg nya övningar på de tomma raderna längst ner och lämna ID tomt – det sätts när vi läser in filen.
A12: Gula rubriker | B12: Kolumner som du fyller i eller kontrollerar. Grå rubriker kommer från appen och behöver du inte röra.
A13: Taggarna som redan står | B13: Färdighet, nivå, yta och sällskap på de befintliga raderna är Carls tolkning av filmerna. Rätta det som är fel.
A14: Rullistor | B14: Tryck på pilen i cellen. Listorna ligger på fliken Taggar, där kan du lägga till egna värden.
A15: Kryss | B15: Kolumnerna Boll, Koner, Mål, Vägg, Medspelare, Stege/häckar och Ensam, Med förälder, Med kompis: skriv x när det stämmer, annars tomt.
A16: Flera värden | B16: Färdighet, Erfarenhet, Position och Plats får innehålla flera värden med kommatecken, t.ex. "Första touch, Passning insida". Alla = passar alla.
A17: Tid och måltid | B17: Tid (min) är hur länge momentet tar i ett pass. Måltid (s) används bara för Tidtagning: tiden barnet ska klara.
A18: Nivå (1–5) | B18: Samma nivåer som i klientregistret: 1 Bollkompis, 2 Touchmästare, 3 Dribblare, 4 Spelmotor, 5 Matchvinnare. Ange den lägsta nivå övningen passar för.
A19: Ålder | B19: Ålder från och till i hela år, t.ex. 7 och 10. Appen är gjord för 7–14 år.
A20: Film | B20: Välj film från fliken Filmer (lägg till nya filmer där först, med länk). Start och Slut är sekunder i filmen där momentet börjar och slutar – appen hoppar dit.
A21: Finns film? | B21: Nej = övningen finns i appen som text men saknar film. Röd markering visar vad som återstår att filma.
A22: Fliken Planera pass | B22: Välj övningar i rullistan så räknas tiden ihop mot riktmärket. Kopiera fliken för fler pass.
... A24: Fliken Taggar | B24: Listorna bakom rullistorna. Lägg till egna värden under rätt rubrik.
A26: Exempel
A27: Raden "Bollkänsla och första driv" överst på fliken Övningar är helt ifylld och visar hur en rad ska se ut.
A29: Frågor
A30: Skriv i kolumnen Anteckning (Haris) på raden det gäller, eller till Carl.

Sheet Övningar
A1: Övning | K1: Film | O1: För vem | S1: Vad som behövs | AD1: Övrigt
A2: ID | B2: Övning | C2: Instruktion | D2: Typ | E2: Tid (min) | F2: Måltid (s) | G2: Fas i passet | H2: Område | I2: Färdighet | J2: Nivå (1–5) | K2: Film | L2: Start (s) | M2: Slut (s) | N2: Finns film? | O2: Ålder från | P2: Ålder till | Q2: Erfarenhet | R2: Position | S2: Boll | T2: Koner | U2: Mål | V2: Vägg | W2: Medspelare | X2: Stege/häckar | Y2: Yta | Z2: Ensam | AA2: Med förälder | AB2: Med kompis | AC2: Plats | AD2: Källa i appen | AE2: Anteckning (Haris)
A3: ub1 | B3: Bollkänsla och första driv | C3: Sulan, tårna och in- och utsida på stället, sedan ett lugnt driv över planen med bollen nära. | D3: Övning | E3: 3 | G3: Uppvärmning | H3: Bollkontroll | I3: Jonglering & bollkänsla, Driv | J3: 1 Bollkompis | K3: Uppvärmning + bollkontroll | L3: 1 | M3: 11 | N3: Ja | O3: 7 | P3: 14 | Q3: Alla | R3: Alla | S3: x | T3: x | Y3: Mellan (10×10 m) | Z3: x | AA3: x | AC3: Alla | AD3: CAP-passet del 1 Uppvärmning + bollkontroll, moment 1
A4: ub2 | B4: In- och utsida i sidled | C4: Flytta bollen mellan fötterna och följ med i sidled. Närbilden visar hur nära bollen ska vara. | D4: Övning | E4: 2 | G4: Uppvärmning | H4: Bollkontroll | I4: Jonglering & bollkänsla | J4: 1 Bollkompis | K4: Uppvärmning + bollkontroll | L4: 12 | M4: 26 | N4: Ja | O4: 7 | P4: 14 | Q4: Alla | R4: Alla | S4: x | T4: x | Y4: Mellan (10×10 m) | Z4: x | AA4: x | AC4: Alla | AD4: CAP-passet del 1 Uppvärmning + bollkontroll, moment 2
A5: ub3 | B5: Driv, vändning och riktningsbyte | C5: Driv iväg, vänd med sulan eller insidan och driv tillbaka. Byt riktning vid linjen. | D5: Övning | E5: 3 | G5: Uppvärmning | H5: Bollkontroll | I5: Driv, Vändningar | J5: 1 Bollkompis | K5: Uppvärmning + bollkontroll | L5: 27 | M5: 49 | N5: Ja | O5: 7 | P5: 14 | Q5: Alla | R5: Alla | S5: x | T5: x | Y5: Mellan (10×10 m) | Z5: x | AA5: x | AC5: Alla | AD5: CAP-passet del 1 Uppvärmning + bollkontroll, moment 3
A6: ub4 | B6: Snabba touch till sist | C6: Många snabba touch på kort tid. Avsluta medan det är kul. | D6: Övning | E6: 2 | G6: Uppvärmning | H6: Bollkontroll | I6: Snabba fötter, Jonglering & bollkänsla | J6: 1 Bollkompis | K6: Uppvärmning + bollkontroll | L6: 50 | M6: 66 | N6: Ja | O6: 7 | P6: 14 | Q6: Alla | R6: Alla | S6: x | T6: x | Y6: Mellan (10×10 m) | Z6: x | AA6: x | AC6: Alla | AD6: CAP-passet del 1 Uppvärmning + bollkontroll, moment 4
A7: ft1 | B7: Mottagning med insidan | C7: Haris rullar bollen, barnet tar emot med insidan mellan konerna och spelar tillbaka. Byt fot varannan gång. | D7: Övning | E7: 3 | G7: Huvuddel | H7: Bollkontroll | I7: Första touch | J7: 1 Bollkompis | K7: Första touch | L7: 0 | M7: 13 | N7: Ja | O7: 7 | P7: 14 | Q7: Alla | R7: Alla | S7: x | T7: x | Y7: Mellan (10×10 m) | AA7: x | AB7: x | AC7: Alla | AD7: CAP-passet del 2 Första touch, moment 1
A8: ft2 | B8: Riktad första touch | C8: Ta emot och styr bollen åt sidan i samma touch, spela sedan tillbaka. | D8: Övning | E8: 2 | G8: Huvuddel | H8: Bollkontroll | I8: Första touch | J8: 1 Bollkompis | K8: Första touch | L8: 14 | M8: 21 | N8: Ja | O8: 7 | P8: 14 | Q8: Alla | R8: Alla | S8: x | T8: x | Y8: Mellan (10×10 m) | AA8: x | AB8: x | AC8: Alla | AD8: CAP-passet del 2 Första touch, moment 2
A9: ft3 | B9: Längre bollar på avstånd | C9: Haris spelar från andra sidan konerna. Barnet möter bollen i rörelse och tar den med sig. | D9: Övning | E9: 3 | G9: Huvuddel | H9: Bollkontroll | I9: Första touch | J9: 1 Bollkompis | K9: Första touch | L9: 22 | M9: 41 | N9: Ja | O9: 7 | P9: 14 | Q9: Alla | R9: Alla | S9: x | T9: x | Y9: Mellan (10×10 m) | AA9: x | AB9: x | AC9: Alla | AD9: CAP-passet del 2 Första touch, moment 3
A10: ft4 | B10: Dämpa en studsande boll | C10: Bollen kastas eller studsar in. Dämpa med insida, lår eller sula och lägg den framför dig. | D10: Övning | E10: 2 | G10: Huvuddel | H10: Bollkontroll | I10: Första touch | J10: 1 Bollkompis | K10: Första touch | L10: 42 | M10: 54 | N10: Ja | O10: 7 | P10: 14 | Q10: Alla | R10: Alla | S10: x | T10: x | Y10: Mellan (10×10 m) | AA10: x | AB10: x | AC10: Alla | AD10: CAP-passet del 2 Första touch, moment 4
A11: pa1 | B11: Stödfoten bredvid bollen | C11: Ställ stödfoten intill bollen med tårna mot målet. Filmen ringar in den. | D11: Övning | E11: 2 | G11: Huvuddel | H11: Teknik | I11: Passning insida | J11: 2 Touchmästare | K11: Passningar | L11: 27 | M11: 32 | N11: Ja | O11: 7 | P11: 14 | Q11: Alla | R11: Alla | S11: x | T11: x | Y11: Mellan (10×10 m) | Z11: x | AA11: x | AB11: x | AC11: Alla | AD11: CAP-passet del 3 Passningar, moment 1
A12: pa2 | B12: Insidespassning i konrutan | C12: Passa genom konerna till Haris, med både höger och vänster fot. Räkna passningar i rad. | D12: Övning | E12: 5 | G12: Huvuddel | H12: Teknik | I12: Passning insida | J12: 2 Touchmästare | K12: Passningar | L12: 2 | M12: 15 | N12: Ja | O12: 7 | P12: 14 | Q12: Alla | R12: Alla | S12: x | T12: x | Y12: Mellan (10×10 m) | AA12: x | AB12: x | AC12: Alla | AD12: CAP-passet del 3 Passningar, moment 2
A13: pa3 | B13: Ta emot och passa tillbaka | C13: Ta emot bollen, ett touch, passa tillbaka. Öka tempot när det sitter. | D13: Övning | E13: 3 | G13: Huvuddel | H13: Teknik | I13: Passning insida, Första touch | J13: 2 Touchmästare | K13: Passningar | L13: 16 | M13: 26 | N13: Ja | O13: 7 | P13: 14 | Q13: Alla | R13: Alla | S13: x | T13: x | Y13: Mellan (10×10 m) | AA13: x | AB13: x | AC13: Alla | AD13: CAP-passet del 3 Passningar, moment 3
A14: dr1 | B14: Driv ut till konerna | C14: Driv i fart till konerna längst bort och tillbaka. Få touch, titta upp. | D14: Övning | E14: 4 | G14: Huvuddel | H14: Teknik | I14: Driv | J14: 2 Touchmästare | K14: Dribblingar | L14: 2 | M14: 12 | N14: Ja | O14: 7 | P14: 14 | Q14: Alla | R14: Alla | S14: x | T14: x | Y14: Mellan (10×10 m) | Z14: x | AA14: x | AC14: Alla | AD14: CAP-passet del 4 Dribblingar, moment 1
A15: dr2 | B15: Riktningsbyten vid konerna | C15: Byt riktning med insidan eller utsidan vid varje kon. Bollen stannar nära foten. | D15: Övning | E15: 5 | G15: Huvuddel | H15: Teknik | I15: Dribbling & finter, Vändningar | J15: 2 Touchmästare | K15: Dribblingar | L15: 13 | M15: 29 | N15: Ja | O15: 7 | P15: 14 | Q15: Alla | R15: Alla | S15: x | T15: x | Y15: Mellan (10×10 m) | Z15: x | AA15: x | AC15: Alla | AD15: CAP-passet del 4 Dribblingar, moment 2
A16: dr3 | B16: Fint och vändning i fart | C16: Lägg in en fint före riktningsbytet. Haris visar vid konen. | D16: Övning | E16: 6 | G16: Huvuddel | H16: Teknik | I16: Dribbling & finter | J16: 2 Touchmästare | K16: Dribblingar | L16: 30 | M16: 45 | N16: Ja | O16: 7 | P16: 14 | Q16: Alla | R16: Alla | S16: x | T16: x | Y16: Mellan (10×10 m) | Z16: x | AA16: x | AC16: Alla | AD16: CAP-passet del 4 Dribblingar, moment 3
A17: ko1 | B17: Snabba fötter vid konerna | C17: Tåtouch och sidosteg över bollen. Lätta fötter, blicken upp. | D17: Övning | E17: 2 | G17: Huvuddel | H17: Koordination | I17: Snabba fötter | J17: 3 Dribblare | K17: Koordination | L17: 2 | M17: 10 | N17: Ja | O17: 7 | P17: 14 | Q17: Alla | R17: Alla | S17: x | T17: x | Y17: Mellan (10×10 m) | Z17: x | AA17: x | AC17: Alla | AD17: CAP-passet del 5 Koordination, moment 1
A18: ko2 | B18: Reagera på bollen | C18: Haris rullar bollen åt ena eller andra hållet. Reagera och ta den i första touchen. | D18: Övning | E18: 2 | G18: Huvuddel | H18: Koordination | I18: Reaktion, Första touch | J18: 3 Dribblare | K18: Koordination | L18: 11 | M18: 16 | N18: Ja | O18: 7 | P18: 14 | Q18: Alla | R18: Alla | S18: x | T18: x | Y18: Mellan (10×10 m) | AA18: x | AB18: x | AC18: Alla | AD18: CAP-passet del 5 Koordination, moment 2
A19: ko3 | B19: Konraden och tillbaka med boll | C19: Sidosteg mellan konerna, hämta bollen och driv tillbaka. | D19: Övning | E19: 3 | G19: Huvuddel | H19: Koordination | I19: Snabba fötter, Driv | J19: 3 Dribblare | K19: Koordination | L19: 17 | M19: 31 | N19: Ja | O19: 7 | P19: 14 | Q19: Alla | R19: Alla | S19: x | T19: x | Y19: Mellan (10×10 m) | Z19: x | AA19: x | AC19: Alla | AD19: CAP-passet del 5 Koordination, moment 3
A20: ko4 | B20: Reaktion och passning | C20: Fotarbete, signal från Haris, och direkt en passning. | D20: Övning | E20: 2 | G20: Huvuddel | H20: Koordination | I20: Reaktion, Passning insida | J20: 3 Dribblare | K20: Koordination | L20: 32 | M20: 45 | N20: Ja | O20: 7 | P20: 14 | Q20: Alla | R20: Alla | S20: x | T20: x | Y20: Mellan (10×10 m) | AA20: x | AB20: x | AC20: Alla | AD20: CAP-passet del 5 Koordination, moment 4
A21: ko5 | B21: Fotarbete över bollen | C21: Avsluta med snabba fötter över bollen. | D21: Övning | E21: 1 | G21: Huvuddel | H21: Koordination | I21: Snabba fötter, Balans | J21: 3 Dribblare | K21: Koordination | L21: 46 | M21: 54 | N21: Ja | O21: 7 | P21: 14 | Q21: Alla | R21: Alla | S21: x | T21: x | Y21: Mellan (10×10 m) | Z21: x | AA21: x | AC21: Alla | AD21: CAP-passet del 5 Koordination, moment 5
A22: n2-mv-grepp | B22: Grepp och fotarbete | C22: Händerna i W, fötterna i rörelse. | D22: Övning | G22: Huvuddel | H22: Koordination | I22: Målvaktsspel | J22: 2 Touchmästare | N22: Nej | O22: 7 | P22: 14 | Q22: Alla | R22: Målvakt | S22: x | AA22: x | AC22: Alla | AD22: Utbildningsvägen nivå 2, målvakt + Stigen etapp 2 (e2-mv)
A23: n2-back-stallning | B23: Försvarsställning | C23: Låg tyngdpunkt, sidledes fötter, rätt avstånd. | D23: Övning | G23: Huvuddel | H23: Koordination | I23: Balans, Spelförståelse | J23: 2 Touchmästare | N23: Nej | O23: 7 | P23: 14 | Q23: Alla | R23: Back | T23: x | AA23: x | AC23: Alla | AD23: Utbildningsvägen nivå 2, back + Stigen etapp 2 (e2-back)
A24: n2-mitt-vandning | B24: Vändningar | C24: Ta emot och vänd i samma rörelse. | D24: Övning | G24: Huvuddel | H24: Bollkontroll | I24: Vändningar, Första touch | J24: 2 Touchmästare | N24: Nej | O24: 7 | P24: 14 | Q24: Alla | R24: Mittfältare | S24: x | T24: x | AA24: x | AC24: Alla | AD24: Utbildningsvägen nivå 2, mittfältare + Stigen etapp 2 (e2-mitt)
A25: n2-anf-avslut | B25: Avslut insida | C25: Placerat lågt i hörnet, från båda sidor. | D25: Övning | G25: Huvuddel | H25: Teknik | I25: Avslut | J25: 2 Touchmästare | N25: Nej | O25: 7 | P25: 14 | Q25: Alla | R25: Anfallare | S25: x | U25: x | AA25: x | AC25: Alla | AD25: Utbildningsvägen nivå 2, anfallare + Stigen etapp 2 (e2-anf)
A26: n3-finter | B26: Finter i fart | C26: Kroppsfint, överstegsfint och sax i fart mot kon. | D26: Övning | G26: Huvuddel | H26: Teknik | I26: Dribbling & finter | J26: 3 Dribblare | N26: Nej | O26: 7 | P26: 14 | Q26: Alla | R26: Alla | S26: x | T26: x | Z26: x | AA26: x | AC26: Alla | AD26: Utbildningsvägen nivå 3 + Stigen etapp 3 (e3-finter)
A27: n3-jonglering | B27: Jonglering 20 | C27: Fot, lår och båda fötterna. Målet är tjugo i rad. | D27: Övning | G27: Huvuddel | H27: Bollkontroll | I27: Jonglering & bollkänsla | J27: 3 Dribblare | N27: Nej | O27: 7 | P27: 14 | Q27: Alla | R27: Alla | S27: x | Y27: Liten (5×5 m) | Z27: x | AC27: Alla | AD27: Utbildningsvägen nivå 3
A28: n3-avslut | B28: Avslut från kanten av straffområdet | C28: Vrist och bredsida, efter en touch. | D28: Övning | G28: Huvuddel | H28: Teknik | I28: Avslut | J28: 3 Dribblare | N28: Nej | O28: 7 | P28: 14 | Q28: Alla | R28: Alla | S28: x | U28: x | AA28: x | AC28: Alla | AD28: Utbildningsvägen nivå 3
A29: n3-mv-fall | B29: Fallteknik | C29: Falla mjukt åt båda hållen och komma upp snabbt. | D29: Övning | G29: Huvuddel | H29: Koordination | I29: Målvaktsspel | J29: 3 Dribblare | N29: Nej | O29: 7 | P29: 14 | Q29: Alla | R29: Målvakt | S29: x | AA29: x | AC29: Alla | AD29: Utbildningsvägen nivå 3, målvakt + Stigen etapp 3 (e3-mv)
A30: n3-mv-fotter | B30: Spel med fötterna | C30: Första touch och passning under press, som målvakt. | D30: Övning | G30: Huvuddel | H30: Bollkontroll | I30: Målvaktsspel, Första touch | J30: 3 Dribblare | N30: Nej | O30: 7 | P30: 14 | Q30: Alla | R30: Målvakt | S30: x | AA30: x | AC30: Alla | AD30: Utbildningsvägen nivå 3, målvakt
A31: n3-back-nick | B31: Nickar | C31: Pannan, ögonen öppna, nicka bort och nicka till en lagkamrat. | D31: Övning | G31: Huvuddel | H31: Koordination | I31: Nickar | J31: 3 Dribblare | N31: Nej | O31: 7 | P31: 14 | Q31: Alla | R31: Back | S31: x | AA31: x | AC31: Alla | AD31: Utbildningsvägen nivå 3, back + Stigen etapp 3 (e3-back)
A32: n3-mitt-axel | B32: Titta över axeln innan bollen | C32: Mottagning med motståndare i ryggen. | D32: Övning | G32: Huvuddel | H32: Bollkontroll | I32: Första touch, Spelförståelse | J32: 3 Dribblare | N32: Nej | O32: 7 | P32: 14 | Q32: Alla | R32: Mittfältare | S32: x | AA32: x | AB32: x | AC32: Alla | AD32: Utbildningsvägen nivå 3, mittfältare + Stigen etapp 3 (e3-mitt)
A33: n3-mitt-framat | B33: Första touch framåt | C33: Ta bollen förbi motståndaren i första touchen. | D33: Övning | G33: Huvuddel | H33: Bollkontroll | I33: Första touch, Driv | J33: 3 Dribblare | N33: Nej | O33: 7 | P33: 14 | Q33: Alla | R33: Mittfältare | S33: x | T33: x | AA33: x | AC33: Alla | AD33: Utbildningsvägen nivå 3, mittfältare
A34: n3-anf-touch | B34: Första touch mot mål | C34: Ta emot så att skottet kommer direkt efter. | D34: Övning | G34: Huvuddel | H34: Bollkontroll | I34: Första touch, Avslut | J34: 3 Dribblare | N34: Nej | O34: 7 | P34: 14 | Q34: Alla | R34: Anfallare | S34: x | U34: x | AA34: x | AC34: Alla | AD34: Utbildningsvägen nivå 3, anfallare + Stigen etapp 3 (e3-anf)
A35: n3-anf-vrist | B35: Avslut bredsida och vrist | C35: Hårt och lågt, efter mottagning. | D35: Övning | G35: Huvuddel | H35: Teknik | I35: Avslut | J35: 3 Dribblare | N35: Nej | O35: 7 | P35: 14 | Q35: Alla | R35: Anfallare | S35: x | U35: x | AA35: x | AC35: Alla | AD35: Utbildningsvägen nivå 3, anfallare
A36: n4-press | B36: Första touch under press | C36: Mottagning med en aktiv motståndare. | D36: Övning | G36: Huvuddel | H36: Bollkontroll | I36: Första touch | J36: 4 Spelmotor | N36: Nej | O36: 7 | P36: 14 | Q36: Alla | R36: Alla | S36: x | AA36: x | AB36: x | AC36: Alla | AD36: Utbildningsvägen nivå 4 + Stigen etapp 4 (e4-press)
A37: n4-langa | B37: Långa tillslag | C37: Vristen, lyftet och crossbollen. | D37: Övning | G37: Huvuddel | H37: Teknik | I37: Långa tillslag | J37: 4 Spelmotor | N37: Nej | O37: 7 | P37: 14 | Q37: Alla | R37: Alla | S37: x | AA37: x | AB37: x | AC37: Alla | AD37: Utbildningsvägen nivå 4 + Stigen etapp 4 (e4-langa)
A38: n4-back-inlagg | B38: Inlägg från kanten | C38: Slå inlägget i fart, mot första och bortre stolpen. | D38: Övning | G38: Huvuddel | H38: Teknik | I38: Långa tillslag | J38: 4 Spelmotor | N38: Nej | O38: 7 | P38: 14 | Q38: Alla | R38: Back | S38: x | U38: x | AA38: x | AB38: x | AC38: Alla | AD38: Utbildningsvägen nivå 4, back
A39: n4-mitt-tempo | B39: Tempo och spelvändning | C39: Få touch, lång passning till andra kanten. | D39: Övning | G39: Huvuddel | H39: Teknik | I39: Långa tillslag, Spelförståelse | J39: 4 Spelmotor | N39: Nej | O39: 7 | P39: 14 | Q39: Alla | R39: Mittfältare | S39: x | T39: x | AA39: x | AB39: x | AC39: Alla | AD39: Utbildningsvägen nivå 4, mittfältare
A40: n4-anf-nick | B40: Nickskott | C40: Möta inlägget och styra nicken nedåt. | D40: Övning | G40: Huvuddel | H40: Koordination | I40: Nickar, Avslut | J40: 4 Spelmotor | N40: Nej | O40: 7 | P40: 14 | Q40: Alla | R40: Anfallare | S40: x | U40: x | AA40: x | AC40: Alla | AD40: Utbildningsvägen nivå 4, anfallare
...

Sheet Taggar
A1: Listorna bakom rullistorna på fliken Övningar. Lägg till egna värden under en rubrik, så kommer de med i rullistan (upp till rad 40).
A2: Typ | B2: Ålder | C2: Nivå | D2: Position | E2: Område | F2: Färdighet | G2: Fas i passet | H2: Svårighet | I2: Utrustning | J2: Yta | K2: Sällskap | L2: Plats
A3: Del av pass | B3: 7–8 | C3: Alla | D3: Alla | E3: Bollkontroll | F3: Första touch | G3: Uppvärmning | H3: 1 Bollkompis | I3: Boll | J3: Liten (5×5 m) | K3: Ensam | L3: Alla
A4: Specifik färdighet | B4: 9–10 | C4: Nybörjare | D4: Målvakt | E4: Teknik | F4: Driv | G4: Huvuddel | H4: 2 Touchmästare | I4: Koner | J4: Mellan (10×10 m) | K4: Med förälder | L4: Utomhus
A5: Kunskap | B5: 11–12 | C5: Spelat 1–2 år | D5: Back | E5: Koordination | F5: Vändningar | G5: Avslut | H5: 3 Dribblare | I5: Mål | J5: Stor (halvplan) | K5: Med kompis | L5: Inomhus
A6: Nivåprov | B6: 13–14 | C6: Spelat 3+ år | D6: Mittfältare | E6: Kunskap | F6: Jonglering & bollkänsla | H6: 4 Spelmotor | I6: Vägg | L6: Hemma
D7: Anfallare | F7: Passning insida | H7: 5 Matchvinnare | I7: Medspelare
F8: Långa tillslag | I8: Stege/häckar
F9: Avslut
F10: Dribbling & finter
F11: Nickar
F12: Snabba fötter
F13: Reaktion
F14: Balans
F15: Spelförståelse
F16: Målvaktsspel

Sheet Filmer
A1: Film | B1: Länk (spela upp) | C1: Längd (s) | D1: Träningstid (min) | E1: Område | F1: Antal moment i banken | G1: Original i Drive | H1: Status | I1: Anteckning
A2: Uppvärmning + bollkontroll | B2: https://8bitcat.github.io/cap-online/media/uppvarmning-bollkontroll.mp4 | C2: 66 | D2: 10 | E2: Bollkontroll | F2: =COUNTIF('Övningar'!$K$3:$K$500,A2) | G2: https://drive.google.com/file/d/1cue2ZXWEBrFFyDYEyPELCqxWCRMVhY_s/view | H2: I appen | I2: Del av CAP-passet. 4 moment med start/slut.
A3: Första touch | B3: https://8bitcat.github.io/cap-online/media/forsta-touch.mp4 | C3: 54 | D3: 10 | E3: Bollkontroll | F3: =COUNTIF('Övningar'!$K$3:$K$500,A3) | G3: https://drive.google.com/file/d/1Qq-mIfgJarv7BwjPla10wvayAyLlaSbO/view | H3: I appen | I3: Del av CAP-passet. 4 moment med start/slut.
A4: Passningar | B4: https://8bitcat.github.io/cap-online/media/passningar.mp4 | C4: 32 | D4: 10 | E4: Teknik | F4: =COUNTIF('Övningar'!$K$3:$K$500,A4) | G4: https://drive.google.com/file/d/1zejOW-2uw8jAs-PIGPQBjluhKygmM_x5/view | H4: I appen | I4: Del av CAP-passet. 3 moment med start/slut.
A5: Dribblingar | B5: https://8bitcat.github.io/cap-online/media/dribblingar.mp4 | C5: 49 | D5: 15 | E5: Teknik | F5: =COUNTIF('Övningar'!$K$3:$K$500,A5) | G5: https://drive.google.com/file/d/12a3m67s_FwOBBFN5P00lz0Mv7mILYEFJ/view | H5: I appen | I5: Del av CAP-passet. 3 moment med start/slut.
A6: Koordination | B6: https://8bitcat.github.io/cap-online/media/koordination.mp4 | C6: 54 | D6: 10 | E6: Koordination | F6: =COUNTIF('Övningar'!$K$3:$K$500,A6) | G6: https://drive.google.com/file/d/1xHuc5FMzTAQVoExtvHujGWdkIYvPuclM/view | H6: I appen | I6: Del av CAP-passet. 5 moment med start/slut.
A7: CAP ONLINE – teknik, bollkontroll och koordination | F7: =COUNTIF('Övningar'!$K$3:$K$500,A7) | G7: https://drive.google.com/file/d/1QRk19keshcHTluFjk6jGoonim_CUAVen/view | H7: Inte i appen | I7: Den långa filmen (1,4 GB) i Drive. Inte nedladdad eller klippt än – säg till om den ska in.
A8: Exempel: Passningar (upplagd i admin) | B8: https://8bitcat.github.io/cap-online/media/passningar.mp4 | C8: 32 | D8: 10 | E8: Teknik | F8: =COUNTIF('Övningar'!$K$3:$K$500,A8) | H8: Testfilm | I8: Upplagd i admin som test, samma klipp som Passningar. Kan tas bort.
F9: =IF(A9="","",COUNTIF('Övningar'!$K$3:$K$500,A9))
F10: =IF(A10="","",COUNTIF('Övningar'!$K$3:$K$500,A10))
F11: =IF(A11="","",COUNTIF('Övningar'!$K$3:$K$500,A11))
F12: =IF(A12="","",COUNTIF('Övningar'!$K$3:$K$500,A12))
F13: =IF(A13="","",COUNTIF('Övningar'!$K$3:$K$500,A13))
F14: =IF(A14="","",COUNTIF('Övningar'!$K$3:$K$500,A14))
F15: =IF(A15="","",COUNTIF('Övningar'!$K$3:$K$500,A15))
F16: =IF(A16="","",COUNTIF('Övningar'!$K$3:$K$500,A16))
F17: =IF(A17="","",COUNTIF('Övningar'!$K$3:$K$500,A17))
F18: =IF(A18="","",COUNTIF('Övningar'!$K$3:$K$500,A18))
F19: =IF(A19="","",COUNTIF('Övningar'!$K$3:$K$500,A19))
F20: =IF(A20="","",COUNTIF('Övningar'!$K$3:$K$500,A20))
... F80: =IF(A80="","",COUNTIF('Övningar'!$K$3:$K$500,A80))

Sheet Kunskap
A1: ID | B1: Rubrik | C1: Om vad | D1: Nivå | E1: Position | F1: Status | G1: Källa i appen | H1: Anteckning (Haris)
A2: n1-regler | B2: Så funkar fotboll | C2: Avspark, inkast, hörna och vem som får använda händerna. | D2: 1 Bollkompis | E2: Alla | F2: Finns i appen (med quiz) | G2: Utbildningsvägen nivå 1
A3: n2-titta-upp | B3: Titta upp | C3: Varför de bästa spelarna vet vad som händer innan bollen kommer. | D3: 2 Touchmästare | E3: Alla | F3: Finns i appen (med quiz) | G3: Utbildningsvägen nivå 2
A4: n2-kropp | B4: Mat, sömn och återhämtning | C4: Det som händer mellan passen avgör hur mycket passen ger. | D4: 2 Touchmästare | E4: Alla | F4: Finns i appen (med quiz) | G4: Utbildningsvägen nivå 2
A5: n2-mv-jobb | B5: Målvaktens jobb | C5: Var du står, när du pratar och när du inte får använda händerna. | D5: 2 Touchmästare | E5: Målvakt | F5: Finns i appen (med quiz) | G5: Utbildningsvägen nivå 2
A6: n2-back-jobb | B6: Backens jobb | C6: Sakta ner, vinn bollen, starta anfallet. | D6: 2 Touchmästare | E6: Back | F6: Finns i appen (med quiz) | G6: Utbildningsvägen nivå 2
A7: n2-mitt-jobb | B7: Mittfältarens jobb | C7: Titta över axeln, första touch framåt, hitta passningen. | D7: 2 Touchmästare | E7: Mittfältare | F7: Finns i appen (med quiz) | G7: Utbildningsvägen nivå 2
A8: n2-anf-jobb | B8: Anfallarens jobb | C8: Löpningen, första touchen mot mål och avslutet. | D8: 2 Touchmästare | E8: Anfallare | F8: Finns i appen (med quiz) | G8: Utbildningsvägen nivå 2
A9: n3-lagkamrat | B9: Att vara en bra lagkamrat | C9: Det som gör att tränare och kompisar vill ha dig i laget. | D9: 3 Dribblare | E9: Alla | F9: Finns i appen (med quiz) | G9: Utbildningsvägen nivå 3
A10: n3-back-forsta | B10: Första försvarare | C10: Press, täckning och när man går in i en duell. | D10: 3 Dribblare | E10: Back | F10: Text kommer från Haris | G10: Utbildningsvägen nivå 3
A11: n4-ytor | B11: Spelförståelse: ytor och tid | C11: Var finns platsen, och hur skapar man den? | D11: 4 Spelmotor | E11: Alla | F11: Text kommer från Haris | G11: Utbildningsvägen nivå 4
A12: n4-mv-position | B12: Positionering i målet | C12: Vinklar, avstånd och när man går ut. | D12: 4 Spelmotor | E12: Målvakt | F12: Text kommer från Haris | G12: Utbildningsvägen nivå 4
A13: n4-mv-prat | B13: Kommunikation | C13: Vad målvakten säger, och när. | D13: 4 Spelmotor | E13: Målvakt | F13: Text kommer från Haris | G13: Utbildningsvägen nivå 4
... A19: n5-mitt-dirigera | B19: Dirigera laget | C19: Rösten, tempot och ansvaret. | D19: 5 Matchvinnare | E19: Mittfältare | F19: Text kommer från Haris | G19: Utbildningsvägen nivå 5

Sheet Planera pass
A1: Planera ett pass
A2: Välj övningar i rullistan i kolumn B. Tid, fas, film och nivå hämtas från fliken Övningar. Gula celler fyller du i. Kopiera fliken (högerklicka på fliknamnet) för fler pass.
A4: Pass | B4: Pass med Haris
A5: Spelare
A6: Datum
A7: Riktmärke (min) | B7: 55
A9: # | B9: Övning | C9: Tid (min) | D9: Fas i passet | E9: Film | F9: Nivå (1–5) | G9: Anteckning
A10: 1 | B10: Bollkänsla och första driv | C10: =IF($B10="","",IFERROR(INDEX('Övningar'!$E$3:$E$500,MATCH($B10,'Övningar'!$B$3:$B$500,0)),"")) | D10: =IF($B10="","",IFERROR(INDEX('Övningar'!$G$3:$G$500,MATCH($B10,'Övningar'!$B$3:$B$500,0)),"")) | E10: =IF($B10="","",IFERROR(INDEX('Övningar'!$K$3:$K$500,MATCH($B10,'Övningar'!$B$3:$B$500,0)),"")) | F10: =IF($B10="","",IFERROR(INDEX('Övningar'!$J$3:$J$500,MATCH($B10,'Övningar'!$B$3:$B$500,0)),"")) | G10: Exempelrader – byt ut mot ditt eget pass.
A11: 2 | B11: Mottagning med insidan | C11: =IF($B11="","",IFERROR(INDEX('Övningar'!$E$3:$E$500,MATCH($B11,'Övningar'!$B$3:$B$500,0)),"")) | D11: =IF($B11="","",IFERROR(INDEX('Övningar'!$G$3:$G$500,MATCH($B11,'Övningar'!$B$3:$B$500,0)),"")) | E11: =IF($B11="","",IFERROR(INDEX('Övningar'!$K$3:$K$500,MATCH($B11,'Övningar'!$B$3:$B$500,0)),"")) | F11: =IF($B11="","",IFERROR(INDEX('Övningar'!$J$3:$J$500,MATCH($B11,'Övningar'!$B$3:$B$500,0)),""))
A12: 3 | B12: Insidespassning i konrutan | C12: =IF($B12="","",IFERROR(INDEX('Övningar'!$E$3:$E$500,MATCH($B12,'Övningar'!$B$3:$B$500,0)),"")) | D12: =IF($B12="","",IFERROR(INDEX('Övningar'!$G$3:$G$500,MATCH($B12,'Övningar'!$B$3:$B$500,0)),"")) | E12: =IF($B12="","",IFERROR(INDEX('Övningar'!$K$3:$K$500,MATCH($B12,'Övningar'!$B$3:$B$500,0)),"")) | F12: =IF($B12="","",IFERROR(INDEX('Övningar'!$J$3:$J$500,MATCH($B12,'Övningar'!$B$3:$B$500,0)),""))
A13: 4 | B13: Fint och vändning i fart | C13: =IF($B13="","",IFERROR(INDEX('Övningar'!$E$3:$E$500,MATCH($B13,'Övningar'!$B$3:$B$500,0)),"")) | D13: =IF($B13="","",IFERROR(INDEX('Övningar'!$G$3:$G$500,MATCH($B13,'Övningar'!$B$3:$B$500,0)),"")) | E13: =IF($B13="","",IFERROR(INDEX('Övningar'!$K$3:$K$500,MATCH($B13,'Övningar'!$B$3:$B$500,0)),"")) | F13: =IF($B13="","",IFERROR(INDEX('Övningar'!$J$3:$J$500,MATCH($B13,'Övningar'!$B$3:$B$500,0)),""))
A14: 5 | B14: Snabba fötter vid konerna | C14: =IF($B14="","",IFERROR(INDEX('Övningar'!$E$3:$E$500,MATCH($B14,'Övningar'!$B$3:$B$500,0)),"")) | D14: =IF($B14="","",IFERROR(INDEX('Övningar'!$G$3:$G$500,MATCH($B14,'Övningar'!$B$3:$B$500,0)),"")) | E14: =IF($B14="","",IFERROR(INDEX('Övningar'!$K$3:$K$500,MATCH($B14,'Övningar'!$B$3:$B$500,0)),"")) | F14: =IF($B14="","",IFERROR(INDEX('Övningar'!$J$3:$J$500,MATCH($B14,'Övningar'!$B$3:$B$500,0)),""))
A15: 6 | C15: =IF($B15="","",IFERROR(INDEX('Övningar'!$E$3:$E$500,MATCH($B15,'Övningar'!$B$3:$B$500,0)),"")) | D15: =IF($B15="","",IFERROR(INDEX('Övningar'!$G$3:$G$500,MATCH($B15,'Övningar'!$B$3:$B$500,0)),"")) | E15: =IF($B15="","",IFERROR(INDEX('Övningar'!$K$3:$K$500,MATCH($B15,'Övningar'!$B$3:$B$500,0)),"")) | F15: =IF($B15="","",IFERROR(INDEX('Övningar'!$J$3:$J$500,MATCH($B15,'Övningar'!$B$3:$B$500,0)),""))
A16: 7 | C16: =IF($B16="","",IFERROR(INDEX('Övningar'!$E$3:$E$500,MATCH($B16,'Övningar'!$B$3:$B$500,0)),"")) | D16: =IF($B16="","",IFERROR(INDEX('Övningar'!$G$3:$G$500,MATCH($B16,'Övningar'!$B$3:$B$500,0)),"")) | E16: =IF($B16="","",IFERROR(INDEX('Övningar'!$K$3:$K$500,MATCH($B16,'Övningar'!$B$3:$B$500,0)),"")) | F16: =IF($B16="","",IFERROR(INDEX('Övningar'!$J$3:$J$500,MATCH($B16,'Övningar'!$B$3:$B$500,0)),""))
A17: 8 | C17: =IF($B17="","",IFERROR(INDEX('Övningar'!$E$3:$E$500,MATCH($B17,'Övningar'!$B$3:$B$500,0)),"")) | D17: =IF($B17="","",IFERROR(INDEX('Övningar'!$G$3:$G$500,MATCH($B17,'Övningar'!$B$3:$B$500,0)),"")) | E17: =IF($B17="","",IFERROR(INDEX('Övningar'!$K$3:$K$500,MATCH($B17,'Övningar'!$B$3:$B$500,0)),"")) | F17: =IF($B17="","",IFERROR(INDEX('Övningar'!$J$3:$J$500,MATCH($B17,'Övningar'!$B$3:$B$500,0)),""))
A18: 9 | C18: =IF($B18="","",IFERROR(INDEX('Övningar'!$E$3:$E$500,MATCH($B18,'Övningar'!$B$3:$B$500,0)),"")) | D18: =IF($B18="","",IFERROR(INDEX('Övningar'!$G$3:$G$500,MATCH($B18,'Övningar'!$B$3:$B$500,0)),"")) | E18: =IF($B18="","",IFERROR(INDEX('Övningar'!$K$3:$K$500,MATCH($B18,'Övningar'!$B$3:$B$500,0)),"")) | F18: =IF($B18="","",IFERROR(INDEX('Övningar'!$J$3:$J$500,MATCH($B18,'Övningar'!$B$3:$B$500,0)),""))
A19: 10 | C19: =IF($B19="","",IFERROR(INDEX('Övningar'!$E$3:$E$500,MATCH($B19,'Övningar'!$B$3:$B$500,0)),"")) | D19: =IF($B19="","",IFERROR(INDEX('Övningar'!$G$3:$G$500,MATCH($B19,'Övningar'!$B$3:$B$500,0)),"")) | E19: =IF($B19="","",IFERROR(INDEX('Övningar'!$K$3:$K$500,MATCH($B19,'Övningar'!$B$3:$B$500,0)),"")) | F19: =IF($B19="","",IFERROR(INDEX('Övningar'!$J$3:$J$500,MATCH($B19,'Övningar'!$B$3:$B$500,0)),""))
A20: 11 | C20: =IF($B20="","",IFERROR(INDEX('Övningar'!$E$3:$E$500,MATCH($B20,'Övningar'!$B$3:$B$500,0)),"")) | D20: =IF($B20="","",IFERROR(INDEX('Övningar'!$G$3:$G$500,MATCH($B20,'Övningar'!$B$3:$B$500,0)),"")) | E20: =IF($B20="","",IFERROR(INDEX('Övningar'!$K$3:$K$500,MATCH($B20,'Övningar'!$B$3:$B$500,0)),"")) | F20: =IF($B20="","",IFERROR(INDEX('Övningar'!$J$3:$J$500,MATCH($B20,'Övningar'!$B$3:$B$500,0)),""))
A21: 12 | C21: =IF($B21="","",IFERROR(INDEX('Övningar'!$E$3:$E$500,MATCH($B21,'Övningar'!$B$3:$B$500,0)),"")) | D21: =IF($B21="","",IFERROR(INDEX('Övningar'!$G$3:$G$500,MATCH($B21,'Övningar'!$B$3:$B$500,0)),"")) | E21: =IF($B21="","",IFERROR(INDEX('Övningar'!$K$3:$K$500,MATCH($B21,'Övningar'!$B$3:$B$500,0)),"")) | F21: =IF($B21="","",IFERROR(INDEX('Övningar'!$J$3:$J$500,MATCH($B21,'Övningar'!$B$3:$B$500,0)),""))
B22: Totalt | C22: =SUM(C10:C21)
B23: Kvar till riktmärket | C23: =$B$7-C22
